<robot name="robot_arm">
    <link name="base_link">
        <visual>
		    <origin xyz="0 0 -0.0001" rpy="0 0 0"/>
			<geometry>
				<box size="0.32 0.26 0.085"/>
			</geometry>
			<material name="Cyan1">
	       		<color rgba="0 0.9 0.9 0.5"/>
	     	</material>
		</visual>
    </link>
    <link name="frame0_origin">
        <visual>
            <origin xyz="0 0 0" rpy="0 0 0"/>
			<geometry>
				<box size="0.01 0.01 0.01"/>
			</geometry>
			<material name="Cyan1">
	       		<color rgba="0 0.9 0.9 0.5"/>
	     	</material>
        </visual>
    </link>
    <link name="link0">
        <visual>
            <origin xyz="0 0 -0.5" rpy = "0 0 0"/>
            <geometry>
                <cylinder radius="0.1" length="1.0"/>
            </geometry>
            <material>
                <color rgba = "0.8 0.8 0 0.8" />
            </material>
        </visual>
    </link>
    <link name="link1">
        <visual>
            <origin xyz="0.5 0 0" rpy = "0 1.5707963268 0"/>
            <geometry>
                <cylinder radius="0.1" length="1.0"/>
            </geometry>
            <material>
                <color rgba = "0.8 0 0.8 0.8" />
            </material>
        </visual>
    </link>
    <link name = "show_joint1">
        <visual>
            <origin xyz="0 0 0" rpy = "0 0 0"/>
            <geometry>
                <cylinder radius="0.15" length="0.4"/>
            </geometry>
            <material>
                <color rgba = "0.8 0.8 0.8 0.4" />
            </material>
        </visual>
    </link>
    <link name="link2">
        <visual>
            <origin xyz="0.5 0 0" rpy = " 0 1.5707963268 0"/>
            <geometry>
                <cylinder radius="0.1" length="1.0"/>
            </geometry>
            <material>
                <color rgba = "0 0.8 0.8 0.8" />
            </material>
        </visual>
    </link>
    <link name = "show_joint2">
        <visual>
            <origin xyz="0 0 0" rpy = "0 0 0"/>
            <geometry>
                <cylinder radius="0.15" length="0.4"/>
            </geometry>
            <material>
                <color rgba = "0.8 0.8 0.8 0.4" />
            </material>
        </visual>
    </link>
    <link name="link3">
        <visual>
            <origin xyz="0 0 0.5" rpy = " 0 0 0"/>
            <geometry>
                <cylinder radius="0.1" length="1.0"/>
            </geometry>
            <material>
                <color rgba = "0.8 0.8 0 0.8" />
            </material>
        </visual>
    </link>
    <link name = "show_joint3">
        <visual>
            <origin xyz="0 0 0" rpy = "0 0 0"/>
            <geometry>
                <cylinder radius="0.15" length="0.4"/>
            </geometry>
            <material>
                <color rgba = "0.8 0.8 0.8 0.4" />
            </material>
        </visual>
    </link>
    <link name = "end_effector">
        <visual>
            <origin xyz="0 0 0" rpy = "0 0 0"/>
            <geometry>
                <box size="0.1 0.1 0.1"/>
            </geometry>
            <material>
                <color rgba = "0.8 0.8 0.8 0.4" />
            </material>
        </visual>
    </link>
    <joint name = "frame_0" type="fixed">
        <parent link="base_link"/>
        <child link="link0"/>
        <origin xyz = " 0 0 1" rpy = "0 0 0"/>
    </joint>
    <joint name = "show_frame0" type="fixed">
        <parent link="base_link"/>
        <child link="frame0_origin"/>
        <origin xyz = " 0 0 1" rpy = "0 0 0"/>
    </joint>
    <joint name = "frame_1" type="continuous">
        <parent link="link0"/>
        <child link="link1"/>
        <origin xyz = " 0 0 0" rpy = "0 0 0"/>
        <axis xyz = "0 0 1"/>
    </joint>
    <joint name = "show_frame_1" type = "fixed">
        <parent link="link0"/>
        <child link="show_joint1"/>
        <origin xyz = " 0 0 0" rpy = "0 0 0"/>
    </joint>
    <joint name = "frame_2" type="continuous">
        <parent link="link1"/>
        <child link="link2"/>
        <origin xyz = " 1 0 0" rpy = "1.5707963268 1.5707963268 0"/>
        <axis xyz = "0 0 1"/>
    </joint>
    <joint name = "show_frame_2" type = "fixed">
        <parent link="link1"/>
        <child link="show_joint2"/>
        <origin xyz = " 1 0 0" rpy = "1.5707963268 1.5707963268 0"/>
    </joint>
    <joint name = "frame_3" type="continuous">
        <parent link="link2"/>
        <child link="link3"/>
        <origin xyz = " 1 0 0" rpy = "-1.5707963268 0 0"/>
        <axis xyz = "0 0 1"/>
    </joint>
    <joint name = "show_frame_3" type = "fixed">
        <parent link="link2"/>
        <child link="show_joint3"/>
        <origin xyz = " 1 0 0" rpy = "-1.5707963268 0 0"/>
    </joint>
    <joint name = "frame_end" type = "fixed">
        <parent link="link3"/>
        <child link="end_effector"/>
        <origin xyz = " 0 0 1" rpy = "0 0 0"/>
    </joint>
</robot>